Workbook

Sheet 达成转化的商品_-_06_15_2026T14_38_46 (
A1: 预算货币 | B1: 日期范围 | C1: 广告主账户 ID | D1: 广告主账户名称 | E1: 广告组合编号 | F1: 广告组合名称 | G1: 广告活动编号 | H1: 广告活动名称 | I1: 广告组编号 | J1: 广告组名称 | K1: 达成转化的商品的编号 | L1: SKU | M1: 达成转化的商品的名称 | N1: 达成转化的商品的父编号 | O1: 达成转化的商品品牌 | P1: 达成转化的商品品类 | Q1: 达成转化的商品子品类 | R1: 达成转化的商品组 | S1: 转化的商品市场 | T1: 推广的商品 SKU-Advertised product SKU | U1: 推广的商品编号 | V1: 推广的商品名称 | W1: 推广的商品父级编号 | X1: 推广的商品品牌 | Y1: 推广的商品品类 | Z1: 推广的商品子品类 | AA1: 推广的商品组 | AB1: 推广的商品站点-Advertised product marketplace | AC1: 购买量 | AD1: 销售额 | AE1: 已售商品数量 | AF1: 购买量（光环） | AG1: 销售额（光环） | AH1: 已售商品数量（光环） | AI1: 购买量（品牌新客） | AJ1: 销售额（品牌新客） | AK1: 已售商品数量（品牌新客）
A2: USD | B2: 2026年6月4日 - 2026年6月24日 | C2: ="amzn1.ads-account.g.dfa7o7cwdl371d634ew58i919" -> amzn1.ads-account.g.dfa7o7cwdl371d634ew58i919 | D2: BLOOMNEXT | G2: ="585687237024345541" -> 585687237024345541 | H2: XM1-Y10-视频流媒体电视 | I2: ="585478290940566279" -> 585478290940566279 | J2: 广告组 - 6/2/2026 17:17:52.510 | K2: B092QVZGD3 | L2: =VLOOKUP(K2,Sheet1!A:B,2,FALSE) -> SH-BRY10-GY-38 | M2: BRONAX Pillow Slippers for Women and Men | House Slides Shower Sandals | Cushioned Thick Sole 37-38 Grey | N2: B0FX2TG8CW | O2: BRONAX | P2: 6000 Kids' Shoes | Q2: 6015 Dress | R2: Shoes | S2: AMAZON.COM | AB2: AMAZON.COM | AC2: 8 | AD2: 179.98 | AE2: 8 | AF2: 8 | AG2: 179.98 | AH2: 8 | AI2: 4 | AJ2: 88.68 | AK2: 4
A3: USD | B3: 2026年6月9日 - 2026年6月15日 | C3: ="amzn1.ads-account.g.dfa7o7cwdl371d634ew58i919" -> amzn1.ads-account.g.dfa7o7cwdl371d634ew58i919 | D3: BLOOMNEXT | G3: ="585687237024345541" -> 585687237024345541 | H3: XM1-Y10-视频流媒体电视 | I3: ="585478290940566279" -> 585478290940566279 | J3: 广告组 - 6/2/2026 17:17:52.510 | K3: B0FPQYPC74 | L3: =VLOOKUP(K3,Sheet1!A:B,2,FALSE) -> XM1-Y22-BG-35 | M3: BRONAX Womens Platform Slides Summer Slip On EVA Chunky Heel Thick Sole Open Toe House Sandals for Female Girls Size 5 Washable Quick Dry Beige 35 | N3: B0FPQT7RBN | O3: BRONAX | Q3: Unknown | R3: Shoes | S3: AMAZON.COM | AB3: AMAZON.COM | AC3: 0 | AD3: 0 | AE3: 0 | AF3: 0 | AG3: 0 | AH3: 0 | AI3: 0 | AJ3: 0 | AK3: 0
A4: USD | B4: 2026年6月4日 - 2026年6月23日 | C4: ="amzn1.ads-account.g.dfa7o7cwdl371d634ew58i919" -> amzn1.ads-account.g.dfa7o7cwdl371d634ew58i919 | D4: BLOOMNEXT | G4: ="585687237024345541" -> 585687237024345541 | H4: XM1-Y10-视频流媒体电视 | I4: ="585478290940566279" -> 585478290940566279 | J4: 广告组 - 6/2/2026 17:17:52.510 | K4: B09ZH8VGHS | L4: =VLOOKUP(K4,Sheet1!A:B,2,FALSE) -> LB1-Y15-GY-40 | M4: BRONAX Shower Slides for Women Men Cushion Bathroom Pillow Slippers Beach Foam Thick Sole Adjustable Double Buckle Pool EVA Sandals Male Size Squishy Grey | N4: B09ZHS5Y7D | O4: BRONAX | P4: 5000 Comfort | Q4: 5075 Men's Slippers | R4: Shoes | S4: AMAZON.COM | AB4: AMAZON.COM | AC4: 0 | AD4: 0 | AE4: 0 | AF4: 0 | AG4: 0 | AH4: 0 | AI4: 0 | AJ4: 0 | AK4: 0
A5: USD | B5: 2026年6月4日 - 2026年6月22日 | C5: ="amzn1.ads-account.g.dfa7o7cwdl371d634ew58i919" -> amzn1.ads-account.g.dfa7o7cwdl371d634ew58i919 | D5: BLOOMNEXT | G5: ="585687237024345541" -> 585687237024345541 | H5: XM1-Y10-视频流媒体电视 | I5: ="585478290940566279" -> 585478290940566279 | J5: 广告组 - 6/2/2026 17:17:52.510 | K5: B0DPKWV55N | L5: =VLOOKUP(K5,Sheet1!A:B,2,FALSE) -> SH-BRY180-WT-40N | M5: BRONAX Arch Support Slides for Women and Mens | Cushioned Thick Sole Pain Relief Slippers 7.5-8.5 Women/6-7 Men White | N5: B0FX2Q73Q6 | O5: BRONAX | P5: 7000 Athletic | Q5: 7025 Womens Sandals/Slides | R5: Shoes | S5: AMAZON.COM | AB5: AMAZON.COM | AC5: 2 | AD5: 47.98 | AE5: 2 | AF5: 2 | AG5: 47.98 | AH5: 2 | AI5: 2 | AJ5: 47.98 | AK5: 2
A6: USD | B6: 2026年6月23日 - 2026年6月24日 | C6: ="amzn1.ads-account.g.dfa7o7cwdl371d634ew58i919" -> amzn1.ads-account.g.dfa7o7cwdl371d634ew58i919 | D6: BLOOMNEXT | G6: ="585687237024345541" -> 585687237024345541 | H6: XM1-Y10-视频流媒体电视 | I6: ="585478290940566279" -> 585478290940566279 | J6: 广告组 - 6/2/2026 17:17:52.510 | K6: B0GFD2G4WH | L6: =VLOOKUP(K6,Sheet1!A:B,2,FALSE) -> XM2-S600-DKBU-36 | M6: BRONAX Womens Wide Width Tennis Sneakers Width Walking Shoes Size 6w Zapatos para Mujer Athletic Sport Thick Cushion Sole Dark Blue 36 | N6: B0H41HL3M6 | O6: BRONAX | Q6: Unknown | R6: Shoes | S6: AMAZON.COM | AB6: AMAZON.COM | AC6: 0 | AD6: 0 | AE6: 0 | AF6: 0 | AG6: 0 | AH6: 0 | AI6: 0 | AJ6: 0 | AK6: 0
A7: USD | B7: 2026年6月18日 - 2026年6月23日 | C7: ="amzn1.ads-account.g.dfa7o7cwdl371d634ew58i919" -> amzn1.ads-account.g.dfa7o7cwdl371d634ew58i919 | D7: BLOOMNEXT | G7: ="585687237024345541" -> 585687237024345541 | H7: XM1-Y10-视频流媒体电视 | I7: ="585478290940566279" -> 585478290940566279 | J7: 广告组 - 6/2/2026 17:17:52.510 | K7: B0GKCXZ16T | L7: =VLOOKUP(K7,Sheet1!A:B,2,FALSE) -> XM2-Y90B-TP-W7 | M7: BRONAX Women's Arch Support Orthopedic Flip Flops Thong Sandals Size 7 Shower Summer Plantar Fasciitis Beach Pool Orthotic Flipflops Female Taupe | N7: B0GKCKCSMJ | O7: BRONAX | P7: 5800 Contemporary | Q7: 5840 Women's Non Tech Athletic | R7: Shoes | S7: AMAZON.COM | AB7: AMAZON.COM | AC7: 0 | AD7: 0 | AE7: 0 | AF7: 0 | AG7: 0 | AH7: 0 | AI7: 0 | AJ7: 0 | AK7: 0
A8: USD | B8: 2026年6月8日 - 2026年6月14日 | C8: ="amzn1.ads-account.g.dfa7o7cwdl371d634ew58i919" -> amzn1.ads-account.g.dfa7o7cwdl371d634ew58i919 | D8: BLOOMNEXT | G8: ="585687237024345541" -> 585687237024345541 | H8: XM1-Y10-视频流媒体电视 | I8: ="585478290940566279" -> 585478290940566279 | J8: 广告组 - 6/2/2026 17:17:52.510 | K8: B0FPQWJ73L | L8: =VLOOKUP(K8,Sheet1!A:B,2,FALSE) -> XM1-Y22-GY-39 | M8: BRONAX Platform Slides for Women EVA Thick Sole Indoor Home Slip On Wedge Heel Female Sandals Summer Breathable Outdoor Beach Slip On Size 9 Grey 39 | N8: B0FPQT7RBN | O8: BRONAX | P8: 7000 Athletic | Q8: 7025 Womens Sandals/Slides | R8: Shoes | S8: AMAZON.COM | AB8: AMAZON.COM | AC8: 0 | AD8: 0 | AE8: 0 | AF8: 0 | AG8: 0 | AH8: 0 | AI8: 0 | AJ8: 0 | AK8: 0
A9: USD | B9: 2026年6月8日 - 2026年6月24日 | C9: ="amzn1.ads-account.g.dfa7o7cwdl371d634ew58i919" -> amzn1.ads-account.g.dfa7o7cwdl371d634ew58i919 | D9: BLOOMNEXT | G9: ="585687237024345541" -> 585687237024345541 | H9: XM1-Y10-视频流媒体电视 | I9: ="585478290940566279" -> 585478290940566279 | J9: 广告组 - 6/2/2026 17:17:52.510 | K9: B0B4K3N8VS | L9: =VLOOKUP(K9,Sheet1!A:B,2,FALSE) -> XM2-S71-PL-39 | M9: BRONAX Womens Wide Tennis Shoes Road Running Jogging Fitness Size 8w Athletics Sports Breathable Mesh Gym Sneakers Zapatos Deportivos De Mujer Pregnant Swollen Purple 39 | N9: B0DK7YD2KT | O9: BRONAX | P9: 7000 Athletic | Q9: 7036 Womens Action Sports | R9: Shoes | S9: AMAZON.COM | AB9: AMAZON.COM | AC9: 0 | AD9: 0 | AE9: 0 | AF9: 0 | AG9: 0 | AH9: 0 | AI9: 0 | AJ9: 0 | AK9: 0
A10: USD | B10: 2026年6月13日 - 2026年6月24日 | C10: ="amzn1.ads-account.g.dfa7o7cwdl371d634ew58i919" -> amzn1.ads-account.g.dfa7o7cwdl371d634ew58i919 | D10: BLOOMNEXT | G10: ="585687237024345541" -> 585687237024345541 | H10: XM1-Y10-视频流媒体电视 | I10: ="585478290940566279" -> 585478290940566279 | J10: 广告组 - 6/2/2026 17:17:52.510 | K10: B09ZH882L7 | L10: =VLOOKUP(K10,Sheet1!A:B,2,FALSE) -> LB1-Y15-GY-41 | M10: BRONAX Shower Slides for Women Men Cushion Pillow Slippers Bathroom Beach Thick Sole Open Toe Double Buckle Pool EVA Sandals Male Size Cozislides Grey | N10: B09ZHS5Y7D | O10: BRONAX | P10: 5000 Comfort | Q10: 5075 Men's Slippers | R10: Shoes | S10: AMAZON.COM | AB10: AMAZON.COM | AC10: 0 | AD10: 0 | AE10: 0 | AF10: 0 | AG10: 0 | AH10: 0 | AI10: 0 | AJ10: 0 | AK10: 0
A11: USD | B11: 2026年6月4日 - 2026年6月23日 | C11: ="amzn1.ads-account.g.dfa7o7cwdl371d634ew58i919" -> amzn1.ads-account.g.dfa7o7cwdl371d634ew58i919 | D11: BLOOMNEXT | G11: ="585687237024345541" -> 585687237024345541 | H11: XM1-Y10-视频流媒体电视 | I11: ="585478290940566279" -> 585478290940566279 | J11: 广告组 - 6/2/2026 17:17:52.510 | K11: B0DSC276H9 | L11: =VLOOKUP(K11,Sheet1!A:B,2,FALSE) -> SH-BRY80-BK-10 | M11: BRONAX Slippers for Women Men Unisex Soft Comfy Summer Shower Shoes House Home Open Toe Chanclas para Mujer Slides Size 10 Indoor Bathroom Outdoor Beach Pool EVA Sole Sandals Black | N11: B0DSBZM8M6 | O11: BRONAX | P11: 5800 Contemporary | Q11: 5870 Women's Slippers | R11: Shoes | S11: AMAZON.COM | AB11: AMAZON.COM | AC11: 0 | AD11: 0 | AE11: 0 | AF11: 0 | AG11: 0 | AH11: 0 | AI11: 0 | AJ11: 0 | AK11: 0
A12: USD | B12: 2026年6月11日 - 2026年6月20日 | C12: ="amzn1.ads-account.g.dfa7o7cwdl371d634ew58i919" -> amzn1.ads-account.g.dfa7o7cwdl371d634ew58i919 | D12: BLOOMNEXT | G12: ="585687237024345541" -> 585687237024345541 | H12: XM1-Y10-视频流媒体电视 | I12: ="585478290940566279" -> 585478290940566279 | J12: 广告组 - 6/2/2026 17:17:52.510 | K12: B0DCV88LGF | L12: =VLOOKUP(K12,Sheet1!A:B,2,FALSE) -> XM2-S75-PL-39 | M12: BRONAX Womens Wide Width Tennis Shoes Wide Toe Box Road Running Sneakers Female Size 8w Slip Resistant Fitness Gym Walking Trendy Lightweight Suede Mesh Purple 39 | N12: B0DCV7KQJM | O12: BRONAX | P12: 5000 Comfort | Q12: 5045 Men's Non Tech Athletic | R12: Shoes | S12: AMAZON.COM | AB12: AMAZON.COM | AC12: 0 | AD12: 0 | AE12: 0 | AF12: 0 | AG12: 0 | AH12: 0 | AI12: 0 | AJ12: 0 | AK12: 0
A13: USD | B13: 2026年6月13日 - 2026年6月23日 | C13: ="amzn1.ads-account.g.dfa7o7cwdl371d634ew58i919" -> amzn1.ads-account.g.dfa7o7cwdl371d634ew58i919 | D13: BLOOMNEXT | G13: ="585687237024345541" -> 585687237024345541 | H13: XM1-Y10-视频流媒体电视 | I13: ="585478290940566279" -> 585478290940566279 | J13: 广告组 - 6/2/2026 17:17:52.510 | K13: B0DCV8VNCS | L13: =VLOOKUP(K13,Sheet1!A:B,2,FALSE) -> XM2-S75-GY-43 | M13: BRONAX Womens Wide Toe Box Road Running Shoes Size 11w Width Sneakers Female Lady Suede Mesh Walking Gym Outdoor Rubber Outsole Stylish Jogging Lace Up Grey 43 | N13: B0DCV7KQJM | O13: BRONAX | P13: 7000 Athletic | Q13: 7036 Womens Action Sports | R13: Shoes | S13: AMAZON.COM | AB13: AMAZON.COM | AC13: 0 | AD13: 0 | AE13: 0 | AF13: 0 | AG13: 0 | AH13: 0 | AI13: 0 | AJ13: 0 | AK13: 0
A14: USD | B14: 2026年6月5日 - 2026年6月12日 | C14: ="amzn1.ads-account.g.dfa7o7cwdl371d634ew58i919" -> amzn1.ads-account.g.dfa7o7cwdl371d634ew58i919 | D14: BLOOMNEXT | G14: ="585687237024345541" -> 585687237024345541 | H14: XM1-Y10-视频流媒体电视 | I14: ="585478290940566279" -> 585478290940566279 | J14: 广告组 - 6/2/2026 17:17:52.510 | K14: B0CGDD9SZ4 | L14: =VLOOKUP(K14,Sheet1!A:B,2,FALSE) -> XM2-S73-ABK-36 | M14: BRONAX Womens Wide Road Running Shoes Tennis Walking Lace up Size 5.5w Lightweght Athletics Comfortable Female Cushion Sole Footwear Pregnant Pregnancy All Black 36 | N14: B0DK7YD2KT | O14: BRONAX | P14: 7000 Athletic | Q14: 7036 Womens Action Sports | R14: Shoes | S14: AMAZON.COM | AB14: AMAZON.COM | AC14: 0 | AD14: 0 | AE14: 0 | AF14: 0 | AG14: 0 | AH14: 0 | AI14: 0 | AJ14: 0 | AK14: 0
A15: USD | B15: 2026年6月6日 - 2026年6月23日 | C15: ="amzn1.ads-account.g.dfa7o7cwdl371d634ew58i919" -> amzn1.ads-account.g.dfa7o7cwdl371d634ew58i919 | D15: BLOOMNEXT | G15: ="585687237024345541" -> 585687237024345541 | H15: XM1-Y10-视频流媒体电视 | I15: ="585478290940566279" -> 585478290940566279 | J15: 广告组 - 6/2/2026 17:17:52.510 | K15: B09ZHCQY1N | L15: =VLOOKUP(K15,Sheet1!A:B,2,FALSE) -> LB1-Y15-BN-43 | M15: BRONAX Pillow Slippers Shower Slides for women Mens Bathroom Beach House Cushion Quick Drying Pool EVA Extra Thick Sole Sandals Size Male Cozislides Brown | N15: B09ZHS5Y7D | O15: BRONAX | P15: 5000 Comfort | Q15: 5055 Men's Sandals | R15: Shoes | S15: AMAZON.COM | AB15: AMAZON.COM | AC15: 0 | AD15: 0 | AE15: 0 | AF15: 0 | AG15: 0 | AH15: 0 | AI15: 0 | AJ15: 0 | AK15: 0
A16: USD | B16: 2026年6月15日 - 2026年6月15日 | C16: ="amzn1.ads-account.g.dfa7o7cwdl371d634ew58i919" -> amzn1.ads-account.g.dfa7o7cwdl371d634ew58i919 | D16: BLOOMNEXT | G16: ="585687237024345541" -> 585687237024345541 | H16: XM1-Y10-视频流媒体电视 | I16: ="585478290940566279" -> 585478290940566279 | J16: 广告组 - 6/2/2026 17:17:52.510 | K16: B0BCJZQ385 | L16: =VLOOKUP(K16,Sheet1!A:B,2,FALSE) -> SH-BRS71-ABK-43N | M16: BRONAX Mens Wide Toe Box Running Tennis Shoes Gym Tennis Athletics Size 9.5 Sports Mesh Walking Rubber Outsole Sneakers for Male Black 43 | N16: B0DGCM33J2 | O16: BRONAX | P16: 7000 Athletic | Q16: 7006 Mens Racquet Sports | R16: Shoes | S16: AMAZON.COM | AB16: AMAZON.COM | AC16: 0 | AD16: 0 | AE16: 0 | AF16: 0 | AG16: 0 | AH16: 0 | AI16: 0 | AJ16: 0 | AK16: 0
A17: USD | B17: 2026年6月4日 - 2026年6月24日 | C17: ="amzn1.ads-account.g.dfa7o7cwdl371d634ew58i919" -> amzn1.ads-account.g.dfa7o7cwdl371d634ew58i919 | D17: BLOOMNEXT | G17: ="585687237024345541" -> 585687237024345541 | H17: XM1-Y10-视频流媒体电视 | I17: ="585478290940566279" -> 585478290940566279 | J17: 广告组 - 6/2/2026 17:17:52.510 | K17: B09X53Z5LL | L17: =VLOOKUP(K17,Sheet1!A:B,2,FALSE) -> SH-BRY10-WT-43 | M17: BRONAX Pillow Slippers for Women and Men | House Slides Shower Sandals | Cushioned Thick Sole 42-43 White | N17: B0FX2TG8CW | O17: BRONAX | P17: 5000 Comfort | Q17: 5070 Women's Slippers | R17: Shoes | S17: AMAZON.COM | AB17: AMAZON.COM | AC17: 3 | AD17: 63.67 | AE17: 3 | AF17: 3 | AG17: 63.67 | AH17: 3 | AI17: 2 | AJ17: 39.68 | AK17: 2
A18: USD | B18: 2026年6月12日 - 2026年6月14日 | C18: ="amzn1.ads-account.g.dfa7o7cwdl371d634ew58i919" -> amzn1.ads-account.g.dfa7o7cwdl371d634ew58i919 | D18: BLOOMNEXT | G18: ="585687237024345541" -> 585687237024345541 | H18: XM1-Y10-视频流媒体电视 | I18: ="585478290940566279" -> 585478290940566279 | J18: 广告组 - 6/2/2026 17:17:52.510 | K18: B09P4278ZP | L18: =VLOOKUP(K18,Sheet1!A:B,2,FALSE) -> SH-BRS71-BU-43 | M18: BRONAX Mens Wide Toe Box Running Tennis Shoes Gym Tennis Athletics Size 9.5 Sports Mesh Walking Rubber Outsole Sneakers for Male Blue 43 | N18: B0DGCM33J2 | O18: BRONAX | P18: 4000 Men's Shoes | Q18: 4040 Non Tech Athletic | R18: Shoes | S18: AMAZON.COM | AB18: AMAZON.COM | AC18: 0 | AD18: 0 | AE18: 0 | AF18: 0 | AG18: 0 | AH18: 0 | AI18: 0 | AJ18: 0 | AK18: 0
... A26: USD | B26: 2026年6月5日 - 2026年6月15日 | C26: ="amzn1.ads-account.g.dfa7o7cwdl371d634ew58i919" -> amzn1.ads-account.g.dfa7o7cwdl371d634ew58i919 | D26: BLOOMNEXT | G26: ="585687237024345541" -> 585687237024345541 | H26: XM1-Y10-视频流媒体电视 | I26: ="585478290940566279" -> 585478290940566279 | J26: 广告组 - 6/2/2026 17:17:52.510 | K26: B09ZHB4XFB | L26: =VLOOKUP(K26,Sheet1!A:B,2,FALSE) -> LB1-Y15-BG-38 | M26: BRONAX Slides for Women Men Pillow Shower Slippers Bathroom Adjustable Double Buckle Beach Bath Cushion Foam Extra Thick Sole EVA Pool Sandals Size Cozy Beige | N26: B09ZHS5Y7D | O26: BRONAX | P26: 5000 Comfort | Q26: 5050 Women's Sandals | R26: Shoes | S26: AMAZON.COM | AB26: AMAZON.COM | AC26: 1 | AD26: 13.99 | AE26: 1 | AF26: 1 | AG26: 13.99 | AH26: 1 | AI26: 1 | AJ26: 13.99 | AK26: 1
A27: USD | B27: 2026年6月3日 - 2026年6月23日 | C27: ="amzn1.ads-account.g.dfa7o7cwdl371d634ew58i919" -> amzn1.ads-account.g.dfa7o7cwdl371d634ew58i919 | D27: BLOOMNEXT | G27: ="585687237024345541" -> 585687237024345541 | H27: XM1-Y10-视频流媒体电视 | I27: ="585478290940566279" -> 585478290940566279 | J27: 广告组 - 6/2/2026 17:17:52.510 | K27: B0GKDM5444 | L27: =VLOOKUP(K27,Sheet1!A:B,2,FALSE) -> XM2-Y90B-BK-W10 | M27: BRONAX Arch Support Flip Flops Thong Orthopedic Sandals for Women Size 10 Summer Plantar Fasciitis Beach Pool Flat Slides Orthotic Female Black | N27: B0GKCKCSMJ | O27: BRONAX | Q27: Unknown | R27: Shoes | S27: AMAZON.COM | AB27: AMAZON.COM | AC27: 4 | AD27: 49.95 | AE27: 5 | AF27: 4 | AG27: 49.95 | AH27: 5 | AI27: 2 | AJ27: 19.98 | AK27: 2
A28: USD | B28: 2026年6月9日 - 2026年6月23日 | C28: ="amzn1.ads-account.g.dfa7o7cwdl371d634ew58i919" -> amzn1.ads-account.g.dfa7o7cwdl371d634ew58i919 | D28: BLOOMNEXT | G28: ="585687237024345541" -> 585687237024345541 | H28: XM1-Y10-视频流媒体电视 | I28: ="585478290940566279" -> 585478290940566279 | J28: 广告组 - 6/2/2026 17:17:52.510 | K28: B0D45GZN55 | L28: =VLOOKUP(K28,Sheet1!A:B,2,FALSE) -> XM2-S73-GN-38 | M28: BRONAX Wide Tennis Shoes for Women Lace up Comfortable Stylish Size 7w Female Road Running Sports Athletics Fitness Footwear Pregnancy Fashion Jogging Sneakers Green 38 | N28: B0DK7YD2KT | O28: BRONAX | P28: 1000 Women's Private Label Shoes | Q28: 1012 Women's Heeled Sandals | R28: Shoes | S28: AMAZON.COM | AB28: AMAZON.COM | AC28: 0 | AD28: 0 | AE28: 0 | AF28: 0 | AG28: 0 | AH28: 0 | AI28: 0 | AJ28: 0 | AK28: 0
A29: USD | B29: 2026年6月3日 - 2026年6月23日 | C29: ="amzn1.ads-account.g.dfa7o7cwdl371d634ew58i919" -> amzn1.ads-account.g.dfa7o7cwdl371d634ew58i919 | D29: BLOOMNEXT | G29: ="585687237024345541" -> 585687237024345541 | H29: XM1-Y10-视频流媒体电视 | I29: ="585478290940566279" -> 585478290940566279 | J29: 广告组 - 6/2/2026 17:17:52.510 | K29: B09BN5N29J | L29: =VLOOKUP(K29,Sheet1!A:B,2,FALSE) -> SH-BRY10-OLGN-40 | M29: BRONAX Pillow Slippers for Women and Men | House Slides Shower Sandals | Cushioned Thick Sole 39-40 Olive Green | N29: B0FX2TG8CW | O29: BRONAX | P29: 6000 Kids' Shoes | Q29: 6020 Casual | R29: Shoes | S29: AMAZON.COM | AB29: AMAZON.COM | AC29: 0 | AD29: 0 | AE29: 0 | AF29: 0 | AG29: 0 | AH29: 0 | AI29: 0 | AJ29: 0 | AK29: 0
A30: USD | B30: 2026年6月3日 - 2026年6月24日 | C30: ="amzn1.ads-account.g.dfa7o7cwdl371d634ew58i919" -> amzn1.ads-account.g.dfa7o7cwdl371d634ew58i919 | D30: BLOOMNEXT | G30: ="585687237024345541" -> 585687237024345541 | H30: XM1-Y10-视频流媒体电视 | I30: ="585478290940566279" -> 585478290940566279 | J30: 广告组 - 6/2/2026 17:17:52.510 | K30: B09BN6ZX7M | L30: =VLOOKUP(K30,Sheet1!A:B,2,FALSE) -> SH-BRY10-BU-40 | M30: BRONAX Pillow Slippers for Women and Men | House Slides Shower Sandals | Cushioned Thick Sole 39-40 Blue | N30: B0FX2TG8CW | O30: BRONAX | P30: 5800 Contemporary | Q30: 5870 Women's Slippers | R30: Shoes | S30: AMAZON.COM | AB30: AMAZON.COM | AC30: 10 | AD30: 227.96 | AE30: 10 | AF30: 10 | AG30: 227.96 | AH30: 10 | AI30: 6 | AJ30: 132 | AK30: 6
A31: USD | B31: 2026年6月5日 - 2026年6月20日 | C31: ="amzn1.ads-account.g.dfa7o7cwdl371d634ew58i919" -> amzn1.ads-account.g.dfa7o7cwdl371d634ew58i919 | D31: BLOOMNEXT | G31: ="585687237024345541" -> 585687237024345541 | H31: XM1-Y10-视频流媒体电视 | I31: ="585478290940566279" -> 585478290940566279 | J31: 广告组 - 6/2/2026 17:17:52.510 | K31: B09BN8WRZC | L31: =VLOOKUP(K31,Sheet1!A:B,2,FALSE) -> SH-BRY10-PL-36 | M31: BRONAX Pillow Slippers for Women and Men | House Slides Shower Sandals | Cushioned Thick Sole 35-36 Purple | N31: B0FX2TG8CW | O31: BRONAX | P31: 5900 Classics | Q31: 5950 Women's Sandals | R31: Shoes | S31: AMAZON.COM | AB31: AMAZON.COM | AC31: 0 | AD31: 0 | AE31: 0 | AF31: 0 | AG31: 0 | AH31: 0 | AI31: 0 | AJ31: 0 | AK31: 0
A32: USD | B32: 2026年6月3日 - 2026年6月24日 | C32: ="amzn1.ads-account.g.dfa7o7cwdl371d634ew58i919" -> amzn1.ads-account.g.dfa7o7cwdl371d634ew58i919 | D32: BLOOMNEXT | G32: ="585687237024345541" -> 585687237024345541 | H32: XM1-Y10-视频流媒体电视 | I32: ="585478290940566279" -> 585478290940566279 | J32: 广告组 - 6/2/2026 17:17:52.510 | K32: B092QVGGBZ | L32: =VLOOKUP(K32,Sheet1!A:B,2,FALSE) -> SH-BRY10-PK-40 | M32: BRONAX Pillow Slippers for Women and Men | House Slides Shower Sandals | Cushioned Thick Sole 39-40 Pink | N32: B0FX2TG8CW | O32: BRONAX | P32: 5900 Classics | Q32: 5950 Women's Sandals | R32: Shoes | S32: AMAZON.COM | AB32: AMAZON.COM | AC32: 14 | AD32: 317.22 | AE32: 14 | AF32: 14 | AG32: 317.22 | AH32: 14 | AI32: 9 | AJ32: 201.93 | AK32: 9
A33: USD | B33: 2026年6月7日 - 2026年6月23日 | C33: ="amzn1.ads-account.g.dfa7o7cwdl371d634ew58i919" -> amzn1.ads-account.g.dfa7o7cwdl371d634ew58i919 | D33: BLOOMNEXT | G33: ="585687237024345541" -> 585687237024345541 | H33: XM1-Y10-视频流媒体电视 | I33: ="585478290940566279" -> 585478290940566279 | J33: 广告组 - 6/2/2026 17:17:52.510 | K33: B0CW1BC7BJ | L33: =VLOOKUP(K33,Sheet1!A:B,2,FALSE) -> SH-BRY180-CL-43 | M33: BRONAX Arch Support Slides for Women and Mens | Cushioned Thick Sole Pain Relief Slippers 10.5-11.5 Women/9-10 Men Chocolate | N33: B0FX2Q73Q6 | O33: BRONAX | P33: 5000 Comfort | Q33: 5050 Women's Sandals | R33: Shoes | S33: AMAZON.COM | AB33: AMAZON.COM | AC33: 1 | AD33: 21.64 | AE33: 1 | AF33: 1 | AG33: 21.64 | AH33: 1 | AI33: 1 | AJ33: 21.64 | AK33: 1
A34: USD | B34: 2026年6月8日 - 2026年6月23日 | C34: ="amzn1.ads-account.g.dfa7o7cwdl371d634ew58i919" -> amzn1.ads-account.g.dfa7o7cwdl371d634ew58i919 | D34: BLOOMNEXT | G34: ="585687237024345541" -> 585687237024345541 | H34: XM1-Y10-视频流媒体电视 | I34: ="585478290940566279" -> 585478290940566279 | J34: 广告组 - 6/2/2026 17:17:52.510 | K34: B0FPQW2PP7 | L34: =VLOOKUP(K34,Sheet1!A:B,2,FALSE) -> XM1-Y22-BG-39 | M34: BRONAX Platform Slides for Women EVA Thick Sole Indoor Home Slip On Wedge Heel Female Sandals Summer Breathable Size 9 Outdoor Beach Washable Beige 39 | N34: B0FPQT7RBN | O34: BRONAX | P34: 5000 Comfort | Q34: 5040 Women's Non Tech Athletic | R34: Shoes | S34: AMAZON.COM | AB34: AMAZON.COM | AC34: 0 | AD34: 0 | AE34: 0 | AF34: 0 | AG34: 0 | AH34: 0 | AI34: 0 | AJ34: 0 | AK34: 0
A35: USD | B35: 2026年6月6日 - 2026年6月13日 | C35: ="amzn1.ads-account.g.dfa7o7cwdl371d634ew58i919" -> amzn1.ads-account.g.dfa7o7cwdl371d634ew58i919 | D35: BLOOMNEXT | G35: ="585687237024345541" -> 585687237024345541 | H35: XM1-Y10-视频流媒体电视 | I35: ="585478290940566279" -> 585478290940566279 | J35: 广告组 - 6/2/2026 17:17:52.510 | K35: B08K323M2N | L35: =VLOOKUP(K35,Sheet1!A:B,2,FALSE) -> XM2-KD7-BKBU-30 | M35: BRONAX Little Boys Tenni Shoe Lightweight Size 12 Zapatos para Niños Sneakers for Running Athletic Sports Tennis Gym Little Children Blue 30 | N35: B0CFF747QG | O35: BRONAX | P35: 6000 Kids' Shoes | Q35: 6020 Casual | R35: Shoes | S35: AMAZON.COM | AB35: AMAZON.COM | AC35: 0 | AD35: 0 | AE35: 0 | AF35: 0 | AG35: 0 | AH35: 0 | AI35: 0 | AJ35: 0 | AK35: 0
A36: USD | B36: 2026年6月3日 - 2026年6月22日 | C36: ="amzn1.ads-account.g.dfa7o7cwdl371d634ew58i919" -> amzn1.ads-account.g.dfa7o7cwdl371d634ew58i919 | D36: BLOOMNEXT | G36: ="585687237024345541" -> 585687237024345541 | H36: XM1-Y10-视频流媒体电视 | I36: ="585478290940566279" -> 585478290940566279 | J36: 广告组 - 6/2/2026 17:17:52.510 | K36: B0CN9BGWFS | L36: =VLOOKUP(K36,Sheet1!A:B,2,FALSE) -> SH-BRY180-BN-40 | M36: BRONAX Arch Support Slides for Women and Mens | Cushioned Thick Sole Pain Relief Slippers 7.5-8.5 Women/6-7 Men Brown | N36: B0FX2Q73Q6 | O36: BRONAX | P36: 5000 Comfort | Q36: 5070 Women's Slippers | R36: Shoes | S36: AMAZON.COM | AB36: AMAZON.COM | AC36: 0 | AD36: 0 | AE36: 0 | AF36: 0 | AG36: 0 | AH36: 0 | AI36: 0 | AJ36: 0 | AK36: 0
A37: USD | B37: 2026年6月3日 - 2026年6月11日 | C37: ="amzn1.ads-account.g.dfa7o7cwdl371d634ew58i919" -> amzn1.ads-account.g.dfa7o7cwdl371d634ew58i919 | D37: BLOOMNEXT | G37: ="585687237024345541" -> 585687237024345541 | H37: XM1-Y10-视频流媒体电视 | I37: ="585478290940566279" -> 585478290940566279 | J37: 广告组 - 6/2/2026 17:17:52.510 | K37: B09ZHS5Y7D | L37: =VLOOKUP(K37,Sheet1!A:B,2,FALSE) -> SP-DMJIK4O9FQ35OSSV | M37: BRONAX Pillow Slippers for Women and Men | Adjustable Double Buckle Shower Slides | Cushioned Thick Sole Sandals | N37: -1 | O37: BRONAX | Q37: Unknown | R37: Shoes | S37: AMAZON.COM | AB37: AMAZON.COM | AC37: 0 | AD37: 0 | AE37: 0 | AF37: 0 | AG37: 0 | AH37: 0 | AI37: 0 | AJ37: 0 | AK37: 0
A38: USD | B38: 2026年6月22日 - 2026年6月23日 | C38: ="amzn1.ads-account.g.dfa7o7cwdl371d634ew58i919" -> amzn1.ads-account.g.dfa7o7cwdl371d634ew58i919 | D38: BLOOMNEXT | G38: ="585687237024345541" -> 585687237024345541 | H38: XM1-Y10-视频流媒体电视 | I38: ="585478290940566279" -> 585478290940566279 | J38: 广告组 - 6/2/2026 17:17:52.510 | K38: B0B4JXMZV3 | L38: =VLOOKUP(K38,Sheet1!A:B,2,FALSE) -> XM2-S71-LTBU-43 | M38: BRONAX Womens Wide Road Running Shoes Lace up Tennis Walking Gym Size 11w Lightweght Athletics Comfortable Cushion Cross Training Female Pregnancy Rubber Sole Light Blue 43 | N38: B0DK7YD2KT | O38: BRONAX | P38: 7000 Athletic | Q38: 7036 Womens Action Sports | R38: Shoes | S38: AMAZON.COM | AB38: AMAZON.COM | AC38: 0 | AD38: 0 | AE38: 0 | AF38: 0 | AG38: 0 | AH38: 0 | AI38: 0 | AJ38: 0 | AK38: 0
A39: USD | B39: 2026年6月23日 - 2026年6月24日 | C39: ="amzn1.ads-account.g.dfa7o7cwdl371d634ew58i919" -> amzn1.ads-account.g.dfa7o7cwdl371d634ew58i919 | D39: BLOOMNEXT | G39: ="585687237024345541" -> 585687237024345541 | H39: XM1-Y10-视频流媒体电视 | I39: ="585478290940566279" -> 585478290940566279 | J39: 广告组 - 6/2/2026 17:17:52.510 | K39: B0DCV8JQHC | L39: =VLOOKUP(K39,Sheet1!A:B,2,FALSE) -> XM2-S75-BK-36 | M39: BRONAX Womens Wide Toe Box Tennis Shoes Wide Width Walking Sneakers Size 5.5w Female Casual Athletics Sport Sneakers Suede Mesh Lace up Outdoor Breathable Black 36 | N39: B0DCV7KQJM | O39: BRONAX | P39: 1000 Women's Private Label Shoes | Q39: 1012 Women's Heeled Sandals | R39: Shoes | S39: AMAZON.COM | AB39: AMAZON.COM | AC39: 1 | AD39: 37.99 | AE39: 1 | AF39: 1 | AG39: 37.99 | AH39: 1 | AI39: 1 | AJ39: 37.99 | AK39: 1
A40: USD | B40: 2026年6月11日 - 2026年6月23日 | C40: ="amzn1.ads-account.g.dfa7o7cwdl371d634ew58i919" -> amzn1.ads-account.g.dfa7o7cwdl371d634ew58i919 | D40: BLOOMNEXT | G40: ="585687237024345541" -> 585687237024345541 | H40: XM1-Y10-视频流媒体电视 | I40: ="585478290940566279" -> 585478290940566279 | J40: 广告组 - 6/2/2026 17:17:52.510 | K40: B0FRD7SGR5 | L40: =VLOOKUP(K40,Sheet1!A:B,2,FALSE) -> XM1-L200-DKBU-36 | M40: BRONAX Womens Wide Walking Shoes Running Athletic Tennis Rubber Outsole Sneakers Jogging Female Footwear Size 6 Dark Blue 36 | N40: B0FRQZD9PB | O40: BRONAX | P40: 7000 Athletic | Q40: 7021 Womens Running | R40: Shoes | S40: AMAZON.COM | AB40: AMAZON.COM | AC40: 0 | AD40: 0 | AE40: 0 | AF40: 0 | AG40: 0 | AH40: 0 | AI40: 0 | AJ40: 0 | AK40: 0
A41: USD | B41: 2026年6月3日 - 2026年6月23日 | C41: ="amzn1.ads-account.g.dfa7o7cwdl371d634ew58i919" -> amzn1.ads-account.g.dfa7o7cwdl371d634ew58i919 | D41: BLOOMNEXT | G41: ="585687237024345541" -> 585687237024345541 | H41: XM1-Y10-视频流媒体电视 | I41: ="585478290940566279" -> 585478290940566279 | J41: 广告组 - 6/2/2026 17:17:52.510 | K41: B0CW18S42T | L41: =VLOOKUP(K41,Sheet1!A:B,2,FALSE) -> SH-BRY180-TPL-38 | M41: BRONAX Arch Support Slides for Women and Mens | Cushioned Thick Sole Pain Relief Slippers 6-7 Women/4.5-5.5 Men Purple | N41: B0FX2Q73Q6 | O41: BRONAX | P41: 5000 Comfort | Q41: 5050 Women's Sandals | R41: Shoes | S41: AMAZON.COM | AB41: AMAZON.COM | AC41: 1 | AD41: 23.99 | AE41: 1 | AF41: 1 | AG41: 23.99 | AH41: 1 | AI41: 0 | AJ41: 0 | AK41: 0
A42: USD | B42: 2026年6月3日 - 2026年6月24日 | C42: ="amzn1.ads-account.g.dfa7o7cwdl371d634ew58i919" -> amzn1.ads-account.g.dfa7o7cwdl371d634ew58i919 | D42: BLOOMNEXT | G42: ="585687237024345541" -> 585687237024345541 | H42: XM1-Y10-视频流媒体电视 | I42: ="585478290940566279" -> 585478290940566279 | J42: 广告组 - 6/2/2026 17:17:52.510 | K42: B0CRRHFKN7 | L42: =VLOOKUP(K42,Sheet1!A:B,2,FALSE) -> SH-BRY180-BK-47 | M42: BRONAX Arch Support Slides for Women and Mens | Cushioned Thick Sole Pain Relief Slippers 13.5-14.5 Women/11.5-12.5 Men Black | N42: B0FX2Q73Q6 | O42: BRONAX | P42: 5000 Comfort | Q42: 5055 Men's Sandals | R42: Shoes | S42: AMAZON.COM | AB42: AMAZON.COM | AC42: 7 | AD42: 139.93 | AE42: 7 | AF42: 7 | AG42: 139.93 | AH42: 7 | AI42: 1 | AJ42: 19.99 | AK42: 1
A43: USD | B43: 2026年6月3日 - 2026年6月24日 | C43: ="amzn1.ads-account.g.dfa7o7cwdl371d634ew58i919" -> amzn1.ads-account.g.dfa7o7cwdl371d634ew58i919 | D43: BLOOMNEXT | G43: ="585687237024345541" -> 585687237024345541 | H43: XM1-Y10-视频流媒体电视 | I43: ="585478290940566279" -> 585478290940566279 | J43: 广告组 - 6/2/2026 17:17:52.510 | K43: B0CW661951 | L43: =VLOOKUP(K43,Sheet1!A:B,2,FALSE) -> SH-BRY180-BN-41N | M43: BRONAX Arch Support Slides for Women and Mens | Cushioned Thick Sole Pain Relief Slippers 9-10 Women/7.5-8.5 Men Brown | N43: B0FX2Q73Q6 | O43: BRONAX | P43: 5000 Comfort | Q43: 5050 Women's Sandals | R43: Shoes | S43: AMAZON.COM | AB43: AMAZON.COM | AC43: 1 | AD43: 23.99 | AE43: 1 | AF43: 1 | AG43: 23.99 | AH43: 1 | AI43: 0 | AJ43: 0 | AK43: 0
A44: USD | B44: 2026年6月18日 - 2026年6月20日 | C44: ="amzn1.ads-account.g.dfa7o7cwdl371d634ew58i919" -> amzn1.ads-account.g.dfa7o7cwdl371d634ew58i919 | D44: BLOOMNEXT | G44: ="585687237024345541" -> 585687237024345541 | H44: XM1-Y10-视频流媒体电视 | I44: ="585478290940566279" -> 585478290940566279 | J44: 广告组 - 6/2/2026 17:17:52.510 | K44: B0GFD4NJB1 | L44: =VLOOKUP(K44,Sheet1!A:B,2,FALSE) -> XM2-S600-GY-37.5 | M44: BRONAX Womens Wide Toe Box Walking Shoes Cushion Running Tennis Sneakers Size 7w Comfy Mesh Athletic Rubber Outsole Grey 37.5 | N44: B0H41HL3M6 | O44: BRONAX | P44: 5800 Contemporary | Q44: 5840 Women's Non Tech Athletic | R44: Shoes | S44: AMAZON.COM | AB44: AMAZON.COM | AC44: 0 | AD44: 0 | AE44: 0 | AF44: 0 | AG44: 0 | AH44: 0 | AI44: 0 | AJ44: 0 | AK44: 0
A45: USD | B45: 2026年6月4日 - 2026年6月23日 | C45: ="amzn1.ads-account.g.dfa7o7cwdl371d634ew58i919" -> amzn1.ads-account.g.dfa7o7cwdl371d634ew58i919 | D45: BLOOMNEXT | G45: ="585687237024345541" -> 585687237024345541 | H45: XM1-Y10-视频流媒体电视 | I45: ="585478290940566279" -> 585478290940566279 | J45: 广告组 - 6/2/2026 17:17:52.510 | K45: B0BPX1YSQF | L45: =VLOOKUP(K45,Sheet1!A:B,2,FALSE) -> SH-BRY10-TPL-36 | M45: BRONAX Pillow Slippers for Women and Men | House Slides Shower Sandals | Cushioned Thick Sole 35-36 Light Purple | N45: B0FX2TG8CW | O45: BRONAX | P45: 5000 Comfort | Q45: 5070 Women's Slippers | R45: Shoes | S45: AMAZON.COM | AB45: AMAZON.COM | AC45: 1 | AD45: 23.99 | AE45: 1 | AF45: 1 | AG45: 23.99 | AH45: 1 | AI45: 1 | AJ45: 23.99 | AK45: 1
A46: USD | B46: 2026年6月3日 - 2026年6月23日 | C46: ="amzn1.ads-account.g.dfa7o7cwdl371d634ew58i919" -> amzn1.ads-account.g.dfa7o7cwdl371d634ew58i919 | D46: BLOOMNEXT | G46: ="585687237024345541" -> 585687237024345541 | H46: XM1-Y10-视频流媒体电视 | I46: ="585478290940566279" -> 585478290940566279 | J46: 广告组 - 6/2/2026 17:17:52.510 | K46: B0D2MS5MS1 | L46: =VLOOKUP(K46,Sheet1!A:B,2,FALSE) -> SH-BRS73-DKBU-44 | M46: BRONAX Mens Wide Toe Box Tennis Shoes Training Road Running Fitness Foot Shape Jogging Walking Size 10w Sports Gym Footwear for Male Breathable Mesh Sneakers Dark Bule 44 | N46: B0D2NDY5DD | O46: BRONAX | P46: 7000 Athletic | Q46: 7004 Mens Action Sports | R46: Shoes | S46: AMAZON.COM | AB46: AMAZON.COM | AC46: 0 | AD46: 0 | AE46: 0 | AF46: 0 | AG46: 0 | AH46: 0 | AI46: 0 | AJ46: 0 | AK46: 0
A47: USD | B47: 2026年6月22日 - 2026年6月23日 | C47: ="amzn1.ads-account.g.dfa7o7cwdl371d634ew58i919" -> amzn1.ads-account.g.dfa7o7cwdl371d634ew58i919 | D47: BLOOMNEXT | G47: ="585687237024345541" -> 585687237024345541 | H47: XM1-Y10-视频流媒体电视 | I47: ="585478290940566279" -> 585478290940566279 | J47: 广告组 - 6/2/2026 17:17:52.510 | K47: B0DGCM33J2 | L47: =VLOOKUP(K47,Sheet1!A:B,2,FALSE) -> SH-BRS71New | M47: BRONAX Men's Wide Cushioned Supportive Road Running Shoes | Wide Toe Box | Rubber Outsole | N47: -1 | O47: BRONAX | P47: 7000 Athletic | Q47: 7004 Mens Action Sports | R47: Shoes | S47: AMAZON.COM | AB47: AMAZON.COM | AC47: 0 | AD47: 0 | AE47: 0 | AF47: 0 | AG47: 0 | AH47: 0 | AI47: 0 | AJ47: 0 | AK47: 0
...

Sheet Sheet1
A1: ASIN | B1: 卖家SKU
A2: B0H14S4VPX | B2: DD1-J101
A3: B0H143VHRM | B3: DD1-J101-BE-W10
A4: B0H148CLLW | B4: DD1-J101-BE-W11
A5: B0H13SHK9Q | B5: DD1-J101-BE-W6
A6: B0H13X9SZT | B6: DD1-J101-BE-W7
A7: B0H13V7N1Z | B7: DD1-J101-BE-W8
A8: B0H13W63S9 | B8: DD1-J101-BE-W9
A9: B0H13THYFP | B9: DD1-J101-BK-W10
A10: B0H14418PZ | B10: DD1-J101-BK-W11
A11: B0H148T4Q8 | B11: DD1-J101-BK-W6
A12: B0H145337Y | B12: DD1-J101-BK-W7
... A1533: B0FNRBZ8JL | B1533: Y10Y180-GY-47
